============================= test session starts ==============================
platform linux -- Python 3.10.12, pytest-8.3.3, pluggy-1.5.0
rootdir: /home/james/projects/cs6223/our_proptest_data
plugins: hypothesis-6.112.2, timeout-2.3.1
collected 25 items

doc_and_code/mutants_2/networkx.algorithms.cycles.find_cycle/mutant_1.py F [  4%]
....                                                                     [ 20%]
doc_and_code/mutants_2/networkx.algorithms.cycles.find_cycle/mutant_2.py . [ 24%]
FFF.                                                                     [ 40%]
doc_and_code/mutants_2/networkx.algorithms.cycles.find_cycle/mutant_3.py . [ 44%]
....                                                                     [ 60%]
doc_and_code/mutants_2/networkx.algorithms.cycles.find_cycle/mutant_4.py . [ 64%]
.FFF                                                                     [ 80%]
doc_and_code/mutants_2/networkx.algorithms.cycles.find_cycle/mutant_5.py . [ 84%]
....                                                                     [100%]

=================================== FAILURES ===================================
/home/james/projects/cs6223/our_proptest_data/doc_and_code/mutants_2/networkx.algorithms.cycles.find_cycle/mutant_1.py:13: assert 0 > 0
/home/james/projects/cs6223/our_proptest_data/doc_and_code/mutants_2/networkx.algorithms.cycles.find_cycle/mutant_2.py:27: IndexError: list index out of range
/home/james/projects/cs6223/our_proptest_data/doc_and_code/mutants_2/networkx.algorithms.cycles.find_cycle/mutant_2.py:39: IndexError: list index out of range
/home/james/projects/cs6223/our_proptest_data/doc_and_code/mutants_2/networkx.algorithms.cycles.find_cycle/mutant_2.py:55: assert 0 == -1
/home/james/projects/cs6223/our_proptest_data/doc_and_code/mutants_2/networkx.algorithms.cycles.find_cycle/mutant_4.py:42: hypothesis.errors.FailedHealthCheck: Tests run under @given should return None, but test_violation_of_networkx_algorithms_cycles_find_cycle_3 returned [(0, 1)] instead.
/home/james/projects/cs6223/our_proptest_data/doc_and_code/mutants_2/networkx.algorithms.cycles.find_cycle/mutant_4.py:59: hypothesis.errors.FailedHealthCheck: Tests run under @given should return None, but test_violation_of_networkx_algorithms_cycles_find_cycle_4 returned [(1, 2), (2, 1)] instead.
/home/james/projects/.venv/lib/python3.10/site-packages/networkx/algorithms/traversal/edgedfs.py:130: networkx.exception.NetworkXError: invalid orientation argument.
=========================== short test summary info ============================
FAILED doc_and_code/mutants_2/networkx.algorithms.cycles.find_cycle/mutant_1.py::test_violation_of_networkx_algorithms_cycles_find_cycle_1
FAILED doc_and_code/mutants_2/networkx.algorithms.cycles.find_cycle/mutant_2.py::test_violation_of_networkx_algorithms_cycles_find_cycle_2
FAILED doc_and_code/mutants_2/networkx.algorithms.cycles.find_cycle/mutant_2.py::test_violation_of_networkx_algorithms_cycles_find_cycle_3
FAILED doc_and_code/mutants_2/networkx.algorithms.cycles.find_cycle/mutant_2.py::test_violation_of_networkx_algorithms_cycles_find_cycle_4
FAILED doc_and_code/mutants_2/networkx.algorithms.cycles.find_cycle/mutant_4.py::test_violation_of_networkx_algorithms_cycles_find_cycle_3
FAILED doc_and_code/mutants_2/networkx.algorithms.cycles.find_cycle/mutant_4.py::test_violation_of_networkx_algorithms_cycles_find_cycle_4
FAILED doc_and_code/mutants_2/networkx.algorithms.cycles.find_cycle/mutant_4.py::test_violation_of_networkx_algorithms_cycles_find_cycle_5
========================= 7 failed, 18 passed in 1.87s =========================
